# 5.5章 例外処理

## 5.5.1 throw文とErrorオブジェクト

エラーを表すオブジェクトとしてErrorインスタンスを使う。
エラーを発生させるには `throw` を用いる。

```
console.log('エラーを発生させます');
throwError();
console.log('エラーを発生させました');

function throwError() {
  const error = new Error('エラーが発生しました！');
  throw error;
}
```

エラーが発生すると、スタックトレースが出力され、プログラムの実行はそこでストップする。

## 5.5.2 try-catch

基本形

```
try {
  // tryブロック
} catch (err) {
  // catchブロック
}
```

try内でエラーが発生した時、tryブロックの処理をその時点で終了し、catchブロックに移行します。

```
try {
  console.log('エラーを発生させます');
  throwError();
  console.log('エラーを発生させました');
} catch (err) {
  console.log('エラーをキャッチしました');
  console.log(err);
}
console.log('終わり');

function throwError() {
  throw new Error('エラーが発生しました！！');
}
```

## 5.5.3 例外処理と大域脱出

```
try {
  someFunc();
} catch {
  // 何もしない
}
```

catch 処理の何もないプログラムは、悪い例外処理の典型。最低ログを出すなどするべき。

処理の失敗を表す値は他にもあり、そちらを用いるのも有用になる。

```
function getAverage(nums: number[]) {
  if (nums.length === 0) return undefined;

  return sum(nums) / nums.length;
}
```

この getAverage が失敗したかどうかは戻り値が undefined かどうかで判定できる。
このように失敗を表すには「例外を用いる」「失敗を表す返り値を使う」という方法があり、どちらも一長一短。
基本的には後者（例外を使わない方）を推奨して、理由としては型情報の面で後者のほうが優れているため。

try-catch は型システムの上で非常に扱いにくいものになっている。catch (err) で引数に取っているerrの型が `unknown型` になっている。unknown型はどんな値が入るか全く不明となってしまう。エラーを補足することができても、それに対する詳細な処理を行うことが難しい。

一方で例外処理が有効な場合もあり、それが大域脱出を活かせる場合となる。

大域脱出とは、その場で実行を中断して別の場所にプログラムの制御を移すこと。エラーをthrowで発生させた場合、プログラムがthrowの次へ進むことがない。エラーが発生した時点で、プログラムは中断し、エラーはプログラムの外側へと脱出を始める。プログラムの外側とは、現在の場所がブロックならブロックの外へ、関数の中なら関数の外へ、移動するということ。ある意味では、return文も大域脱出の仲間とも言える。

```
try {
  throwError();
  console.log('これは出力されない'); // tryブロックから脱出するのでここは実行されない
} catch (err) {
  console.log(err);
}

function throwError() {
  throw new Error('エラーが発生しました');
  console.og('これは出力されない'); // 関数から脱出するので、ここは実行されない
}
```

大域脱出は、複数箇所で発生した例外を1箇所で処理できる、という強みもあります。しかし、大域脱出を強いることにもなるため、エラーをそれぞれの箇所で処理したいという場合にはそれぞれで try-catch を書く必要があり、プログラムが複雑になってしまう。そういった場合には例外ではなく、戻り値を以てエラーを処理したほうが見通しのよいプログラムになる。

例外には大域脱出の特徴があるので、エラーが発生したらとにかく処理を中断してエラーをまとめたい時に有効な一方、場合によってエラー処理を変えたい時には例外を使わないほうがわかりやすいプログラムになる。

### 5.5.4 finallyで脱出に割り込む

try-catchの後ろには、finallyを付け加えることができる

finallyブロックは、エラーが発生してもしなくても実行される。

```
try {
  console.log('try');
} catch {
  console.log('catch');
} finally {
  console.log('finally');
}
```

finallyは脱出に割り込むことができる。

```
try {
  console.log('エラーを発生させます');
  throwError();
  console.log('エラーを発生させました');
} finally {
  console.log('finally');
}
console.log('tryの後ろ');

function throwError() {
  throw new Error('エラー発生');
}
```

また、finallyはエラー以外の脱出にも対応している。

```
console.log(sum(100));

function sum(max) {
  try {
    let result = 0;
    for (let i = 1; i <= max; i++) {
      result += i;
    }
    return result;
  } finally {
    console.log('sumから脱出します')
  }
}
```

finallyは「エラーが起きても起きなくても実行する」というより「何が何でも実行する」が正しいかもしれない。
例えば、ファイルをオープンした時、使用後にファイルを必ずクローズする必要があるが、ファイルオープンと同時にtryに入り、finallyブロックでクロースを記述しておくことで、エラーの発生やreturnによる途中脱出などのいかなる場合においても確実にファイルクローズ処理を行うことができる。

EOF