# 8 非同期処理
## 8.3 Promiseを使う
PromiseとはES2015で追加された非同期処理のための機能
非同期処理では「終わったあとに何するのか」が不可欠となっている
コールバック関数ベースの非同期処理では、非同期処理を実行する関数にコールバック関数を渡していたが、Promiseベースの非同期処理では、非同期処理を行う関数は関数を受け取らずPromiseオブジェクトを返すようになっている
そのPromiseオブジェクトに対して終わったあとに行う処理を表す関数を登録する

### 8.3.1 Promise版の fs を使ってみる

```
import { readFile } from "fs/promises";

const p = readFile("foo.txt", "utf8");

p.then((data) => {
  console.log(data);
});
```

p の型は  Promise<string> になっている。このように、Promiseベースの非同期処理を行う関数はPromiseオブジェクトを返す。
Promiseオブジェクトは Promise<T> という方と持ち、型としては型引数を1つもっていて、今回の Promise<string> は「string型の結果を持つPromiseオブジェクト」という意味になる。

例のように Promiseオブジェクトは　 then メソッドを持ち、引数としてコールバック関数を受け取る。渡されたコールバック関数はPromiseオブジェクトが示す非同期処理が完了した時点で呼び出される。

従来のコールバック関数を渡すこととの違いとして「非同期処理を行う関数にコールバック関数を直接渡す」という処理から「非同期処理を行う関数はPromiseオブジェクトを返す」「返されたPrommiseオブジェクトにthenでコールバック関数を返す」という2段階に分離されたことになる。これによって抽象的、統一的に非同期処理を表せるというのがPromiseの特徴です。

Promiseの結果が定まることをPromiseの解決(settlement)と呼び、Promiseが解決されるとthenのコールバック関数が呼び出される。
※Promiseには resolve という概念もあり、こちらを解決とすることもあるが、説明は省略する
https://qiita.com/uhyo/items/a9f6e70f43287cc0f52e

コールバック関数に対してPromiseオブジェクトを挟むことによるメリットとして、コールバック関数を直接渡す方式だと、引数のどこに渡す必要があるかなど都度調べる必要があり、コストが高かった。
一方でPromiseベースであれば常にPromiseオブジェクトが返されることが決まっており、結果も「Promiseの解決」という共通のインターフェースを通して行える。


また、PromiseベースAPIの場合、実際に非同期処理が始まるのは度のタイミングか、ということについては、上の例を利用すると「readFileを呼び出した瞬間に始まっており、Promiseオブジェクトが返り値として返された段階で既に始まっている」が回答になる（＝then が登録されたときではない）


### 8.3.2 コールバック関数の登録とエラー処理（１）

Promiseに対してthenメソッドを用いることで非同期処理が解決した際のコールバック関数を登録していた
同じPromiseオブジェクトに対して、複数個のthenメソッドの呼び出しができ、解決時にはすべてのthenメソッドが呼び出される
呼び出しは登録された順番に呼び出される


```
import { readFile } from 'fs/promises';

const promise = readFile("foo.txt, "utf8");

promise.then((result) => console.log("1"));
promise.then((result) => console.log("2"));
promise.then((result) => console.log("3"));
```

この例では、readFileの処理が成功すれば、1,2,3の順に出力される
Promiseには失敗の可能性もある。そのため、失敗を表す機能がある
Promiseオブジェクトの解決(settlement)には、成功(fulfill)と失敗(reject)の2種類がある
失敗時には `catch` メソッドを用いる

```
import { readFile } from 'fs/promises';

const primise = readFile("foo.txt", "utf8");

promise.then((result) => console.log('fulfill', result));
promise.catch((error) => console.log('reject', error));
```



tips: thenメソッドには成功と失敗の処理を同時に登録する機能がある

```
import { readFile } from 'fs/promises';

const primise = readFile("foo.txt", "utf8");

promise.then(
  (result) => console.log('fulfill', result),
  (error) => console.log('reject', error);
);
```


### 8.3.3 コールバック関数の登録とエラー処理（２）

`finally` メソッドの存在

try文の finally と同じで、成功と失敗のどちらにも呼び出される関数を登録できる

```
import { readFile } from 'fs/promises';

const primise = readFile("foo.txt", "utf8");

promise.then((result) => console.log('fulfill', result));
promise.catch((error) => console.log('reject', error));
promise.finally(() => console.log('finished'));
```



### 8.3.4 自分でPromiseオブジェクトを作る

3秒後に成功するPromiseを作ってみるとこんな感じになる

```
const promise = new Promise<number>((resolve) => {
  setTimeout(() => {
    resolve(100);
  }, 3000);
});

promise.then((num) => console.log(`結果は${num}です`));
```

Promiseコンストラクターは１つの型引数（結果の型）と、１つの引数を持つ
今回は型引数としてnumberを持ち、引数は (resolve) => { ... } という関数（executorと呼ぶ）

executor関数には引数として関数が渡されるが、この引数名はresolveという名前にするのが通例
resolveの関数が呼び出されることでPromiseは成功裏に解決される

sleepメソッドの実装

```
const sleep = (duration: number) => {
  return new Promise<void>((resolve) => {
    setTimeout(resolve, duration);
  })
};

sleep(3000).then(() => console.log('3秒経ちました'));
```

executor関数には第2引数があり、失敗を表すコールバック関数を登録できる

```
const sleepReject = (duration: number) => {
  return new Promise<never>((_resolve, reject) => {
    setTimeout(reject, duration);
  });
};

sleepReject(3000).catch(() => console.log('rejected'));
```

実行すると3秒後には rejected が出力されるでしょう

実際の実装では resolve, reject を適切に実装しましょう






### 8.3.5 Promiseの静的メソッド（１）
※静的メソッドとは、Rubyのクラスメソッドの位置づけ

- Promise.resolve
- Promise.reject

それぞれ与えられた引数を結果として即時解決するPromiseオブジェクトを作るためのメソッド

```
// promise1, promise2 は同じ挙動
const promise1 = Promise.resolve(100);
const promise2 = new Promise((resolve) => resolve(100));

// promise3, promise4 は同じ挙動
const promise3 = Promise.reject('rejected');
const promise4 = new Promise((_resolve, reject) => reject('rejected'));
```

ただし、成功済みのPromiseオブジェクトでも、実行は非同期的なので、下記のような処理は 1, 2 の順で呼ばれる

```
const promise = Promise.resolve();

promise.then(() => console.log('2'));
console.log('1');
```




### 8.3.6 Promiseの静的メソッド（２）

- Promise.all
Promiseオブジェクトを配列として引数に受け取って、それらの非同期処理を並列に実行し、すべてが完了したら次に進むというプログラム
どれか１つでも失敗したらすべて失敗になる


```
import { readFile } from 'fs/promises';

const promise1 = readFile('1.txt');
const promise2 = readFile('2.txt');
const promise3 = readFile('3.txt');

const promiseAll = Promise.all([promise1, promise2, promise3]);

promiseAll.then((results) => {
  console.log(results[0]);
  console.log(results[1]);
  console.log(results[2]);
});
```

- Promise.race
allと同様にPromiseの配列を受け取って、最も早く成功または失敗したものを全体の結果とする

```
import { readFile } from 'fs/promises';

const promise1 = readFile('1.txt');
const promise2 = readFile('2.txt');
const promise3 = readFile('3.txt');

const promiseRace = Promise.race([promise1, promise2, promise3]);

promiseRace.then((result) => {
  console.log(result);
});
```

ユースケースとしては、タイムアウト処理などがある

```
import { readFile } from 'fs/promises';

const sleepReject = (duration: number) => {
  return new Promise<never>((resolve, reject) => {
    setTimeout(reject, duration);
  });
};

const promiseRace = Promise.race([
  sleepReject(5000),
  readFile('hoge.txt')
]);

promiseRace.then((result) => {
  console.log(result);
}, (error: unknown) => {
  console.log('reject', error);
});
```

### 8.3.7 Promiseの静的メソッド（３）

- Promise.allSettled
Promiseの配列を受け取って、受け取ったPromsieすべてが解決したら成功になる
Allと似ているが、Allではいずれかが失敗した時に即座に失敗になるが、allSettledではその場合でもすべてのPromiseが解決するまで処理が継続される
戻り値に対しても、成功したPromiseオブジェクトは `{ status: 'fulfilled', value: 結果の値 }` 失敗したPromiseオブジェクトは `{ status: 'rejected', reason: 結果の値 }` というオブジェクトになる

- Promise.any
Promiseの配列を受けとり、受け取ったPromiseのうちいずれかが成功したらPromise.anyも成功になる
Promise.raceと似ているが、違いとしてはPromise.anyではどれかが失敗したとしても、どれかが成功するまで待つ
つまり、raceでは成功失敗関係なく1番早いものに従う一方、anyでは成功したもののうち、一番早いものに従うことになる
もし、anyに渡されたものがすべて失敗したらanyも失敗になる


### 8.3.8 Promiseチェーン（１）チェーンを作る
### 8.3.9 Promiseチェーン（２）非同期処理の連鎖
### 8.3.10 Promiseチェーン（３）エラーの扱い

いつもの
```
import { readFile } from 'fs/promises';

readFile("foo.txt", "utf8");
  .then((result) => console.log('fulfill', result));
  .catch((error) => console.log('reject', error));
  .finally(() => console.log('finished'));
```

非同期の失敗を成功に変える
```
import { readFile } from 'fs/promises';

readFile("foo.txt", "utf8");
  .catch((error) => console.log(error));
  .then((result) => console.log(result));
```

### 8.3.11 dynamic import

```
import('fs/promises')
  .then(({ readFile }) => readFile('foo.txt', 'utf8'))
  .then((result) => console.log(result))
  .catch((error) => console.log(error))
```











eof
